<?xml version="1.0"?>
<robot name="automatic_cart">

  <!-- Robot Body -->
  <material name="black">
    <color rgba="0 0 0 1"/>
  </material>
  
  <link name="base_link">
    <visual>
      <geometry>
        <mesh filename="package://automatic_cart/models/shopping_cart/meshes/shopping_cart_base.dae"/>
      </geometry>
      <origin xyz="0.0 0.0 0.2"/>
    </visual>
    <collision>
      <geometry>
        <mesh filename="package://automatic_cart/models/shopping_cart/meshes/shopping_cart_base.dae"/>
      </geometry>
      <origin xyz="0.0 0.0 0.2"/>
    </collision>
    <inertial>
      <mass value="30"/>
      <inertia ixx="1.0" ixy="0.0" ixz="0.0" iyy="1.0" iyz="0.0" izz="1.0"/>
    </inertial>
  </link>
  
  <link name="basket">
    <visual>
      <geometry>
        <mesh filename="package://automatic_cart/models/shopping_cart/meshes/shopping_cart_basket.dae"/>
      </geometry>
      <origin xyz="0.0 0.0 -0.2"/>
    </visual>
    <collision>
      <geometry>
        <mesh filename="package://automatic_cart/models/shopping_cart/meshes/shopping_cart_basket.dae"/>
      </geometry>
      <origin xyz="0.0 0.0 -0.2"/>
    </collision>
    <inertial>
      <mass value="10"/>
      <inertia ixx="1.0" ixy="0.0" ixz="0.0" iyy="1.0" iyz="0.0" izz="1.0"/>
    </inertial>
  </link>
  
  <joint name="base_to_basket" type="prismatic">
    <axis xyz="0 0 1"/>
    <limit effort="1000.0" lower="-0.07" upper="0.07" velocity="0.5"/>
    <parent link="base_link"/>
    <child link="basket"/>
    <origin xyz="0.0 0.0 0.4"/>
  </joint>
  
  
  <!-- Wheels -->
  <link name="right_wheel">
    <visual>
      <origin rpy="0 1.57075 0" xyz="0 0 0"/>
      <geometry>
        <cylinder length="0.025" radius="0.08"/>
      </geometry>
      <material name="black"/>
    </visual>
    <collision>
      <origin rpy="0 1.57075 0" xyz="0 0 0"/>
      <geometry>
        <cylinder length="0.025" radius="0.08"/>
      </geometry>
    </collision>
    <inertial>
      <mass value="2"/>
      <inertia ixx="0.0" ixy="0.0" ixz="0.0" iyy="1.0" iyz="0.0" izz="1.0"/>
    </inertial>
  </link>
  <joint name="right_wheel_joint" type="continuous">
    <axis rpy="0 0 0" xyz="1 0 0"/>
    <parent link="base_link"/>
    <child link="right_wheel"/>
    <origin rpy="0 0 0" xyz="0.2 -0.2 -0.11"/>
  </joint>
  
  <link name="left_wheel">
    <visual>
      <origin rpy="0 1.57075 0" xyz="0 0 0"/>
      <geometry>
        <cylinder length="0.025" radius="0.08"/>
      </geometry>
      <material name="black"/>
    </visual>
    <collision>
      <origin rpy="0 1.57075 0" xyz="0 0 0"/>
      <geometry>
        <cylinder length="0.025" radius="0.08"/>
      </geometry>
    </collision>
    <inertial>
      <mass value="2"/>
      <inertia ixx="0.0" ixy="0.0" ixz="0.0" iyy="1.0" iyz="0.0" izz="1.0"/>
    </inertial>
  </link>
  <joint name="left_wheel_joint" type="continuous">
    <axis rpy="0 0 0" xyz="1 0 0"/>
    <parent link="base_link"/>
    <child link="left_wheel"/>
    <origin rpy="0 0 0" xyz="-0.2 -0.2 -0.11"/>
  </joint>
  
  <link name="front_wheel">
    <visual>
      <origin rpy="0 1.57075 0" xyz="0 0 0"/>
      <geometry>
        <cylinder length="0.02" radius="0.047"/>
      </geometry>
      <material name="black"/>
    </visual>
    <collision>
      <origin rpy="0 1.57075 0" xyz="0 0 0"/>
      <geometry>
        <cylinder length="0.02" radius="0.047"/>
      </geometry>
    </collision>
    <inertial>
      <mass value="1"/>
      <inertia ixx="0.0" ixy="0.0" ixz="0.0" iyy="1.0" iyz="0.0" izz="1.0"/>
    </inertial>
  </link>
  <joint name="front_wheel_joint" type="continuous">
    <axis rpy="0 0 0" xyz="1 0 0"/>
    <parent link="base_link"/>
    <child link="front_wheel"/>
    <origin rpy="0 0 0" xyz="0 0.2 -0.15"/>
  </joint>
  
  <!-- Gazebo plugin for ROS Control -->
  <gazebo>
    <plugin name="gazebo_ros_control" filename="libgazebo_ros_control.so">
      <robotNamespace>/</robotNamespace>
    </plugin>
  </gazebo>

</robot>
